Workbook

Sheet Presupuesto General
A1: PRESUPUESTO GENERAL DE OBRA VALORIZADO A ENERO 2026 (GRUPO 7)
A2: Proyecto: Bodegas BSL Quilicura | Cantidades Oficiales Grupo 7 | 41 Partidas Valorizadas con GG (15,27%) y Utilidad (9,00%)
A4: Ítem | B4: Descripción de la Partida | C4: Unid. | D4: Cantidad G7 | E4: PU Costo Directo ($) | F4: Subtotal Costo Directo ($) | G4: Recargo GG (15.27%) ($) | H4: Recargo Utilidad (9.00%) ($) | I4: PU Venta Total ($) | J4: Monto Total Venta ($) | K4: Partida Detallada (APU)
A5: 1.0 MOVIMIENTO DE TIERRAS, FUNDACIONES Y VIALIDAD
A6: 1.1 | B6: Excavación en TCN Caminos | C6: m3 | D6: 466 | E6: 5500 | F6: =D6*E6 | G6: =E6*'Gastos Generales'!G23 | H6: =E6*0.09 | I6: =E6+G6+H6 | J6: =D6*I6 | K6: Precio Referencial
A7: 1.2 | B7: Excavación en TCN Bodegas | C7: m3 | D7: 20354 | E7: 5500 | F7: =D7*E7 | G7: =E7*'Gastos Generales'!G23 | H7: =E7*0.09 | I7: =E7+G7+H7 | J7: =D7*I7 | K7: Precio Referencial
A8: 1.3 | B8: Mejoramiento Fundaciones con integral natural (1,5 m.) | C8: m3 | D8: 7740 | E8: 18000 | F8: =D8*E8 | G8: =E8*'Gastos Generales'!G23 | H8: =E8*0.09 | I8: =E8+G8+H8 | J8: =D8*I8 | K8: Precio Referencial
A9: 1.4 | B9: Mejoramiento Fundaciones con integral natural (0,5 m.) | C9: m3 | D9: 2944 | E9: 18000 | F9: =D9*E9 | G9: =E9*'Gastos Generales'!G23 | H9: =E9*0.09 | I9: =E9+G9+H9 | J9: =D9*I9 | K9: Precio Referencial
A10: 1.5 | B10: Relleno Estructural bajo 2" (Fundaciones a Subrasante) | C10: m3 | D10: 2198 | E10: 20000 | F10: =D10*E10 | G10: =E10*'Gastos Generales'!G23 | H10: =E10*0.09 | I10: =E10+G10+H10 | J10: =D10*I10 | K10: Precio Referencial
A11: 1.6 | B11: Relleno Estructural bajo 6" (Fundaciones a Subrasante) | C11: m3 | D11: 3299 | E11: 20000 | F11: =D11*E11 | G11: =E11*'Gastos Generales'!G23 | H11: =E11*0.09 | I11: =E11+G11+H11 | J11: =D11*I11 | K11: Precio Referencial
A12: 1.7 | B12: Relleno Estructural bajo 2" Bodegas, Oficinas, VF | C12: m3 | D12: 3398 | E12: 20000 | F12: =D12*E12 | G12: =E12*'Gastos Generales'!G23 | H12: =E12*0.09 | I12: =E12+G12+H12 | J12: =D12*I12 | K12: Precio Referencial
A13: 1.8 | B13: Terraplén caminos y areas de servicio | C13: m3 | D13: 1955 | E13: 5000 | F13: =D13*E13 | G13: =E13*'Gastos Generales'!G23 | H13: =E13*0.09 | I13: =E13+G13+H13 | J13: =D13*I13 | K13: Precio Referencial
A14: 1.9 | B14: Terraplén bajo radier bodegas | C14: m3 | D14: 1699 | E14: 5000 | F14: =D14*E14 | G14: =E14*'Gastos Generales'!G23 | H14: =E14*0.09 | I14: =E14+G14+H14 | J14: =D14*I14 | K14: Precio Referencial
A15: 1.10 | B15: Preparación de la Subrasante Bodegas | C15: m2 | D15: 16024 | E15: 1500 | F15: =D15*E15 | G15: =E15*'Gastos Generales'!G23 | H15: =E15*0.09 | I15: =E15+G15+H15 | J15: =D15*I15 | K15: Precio Referencial
A16: 1.11 | B16: Preparación de la Subrasante Caminos y Areas de Servicio | C16: m2 | D16: 9756 | E16: 1500 | F16: =D16*E16 | G16: =E16*'Gastos Generales'!G23 | H16: =E16*0.09 | I16: =E16+G16+H16 | J16: =D16*I16 | K16: Precio Referencial
A17: 1.12 | B17: Base Granular Caminos | C17: m3 | D17: 1965 | E17: 21500 | F17: =D17*E17 | G17: =E17*'Gastos Generales'!G23 | H17: =E17*0.09 | I17: =E17+G17+H17 | J17: =D17*I17 | K17: Precio Referencial
A18: 1.13 | B18: Base Granular Bodegas | C18: m3 | D18: 3204 | E18: 21500 | F18: =D18*E18 | G18: =E18*'Gastos Generales'!G23 | H18: =E18*0.09 | I18: =E18+G18+H18 | J18: =D18*I18 | K18: Precio Referencial
A19: 1.14 | B19: Hormigón G-25 radier (malla acma C-92) | C19: m3 | D19: 2403 | E19: 168000 | F19: =D19*E19 | G19: =E19*'Gastos Generales'!G23 | H19: =E19*0.09 | I19: =E19+G19+H19 | J19: =D19*I19 | K19: APU ABIERTO G7
A20: 1.15 | B20: Hormigón G-35 calles | C20: m3 | D20: 1758 | E20: 155000 | F20: =D20*E20 | G20: =E20*'Gastos Generales'!G23 | H20: =E20*0.09 | I20: =E20+G20+H20 | J20: =D20*I20 | K20: Precio Referencial
A21: 1.16 | B21: Hormigón G-25 Fundaciones Zapatas Bodegas y Oficinas | C21: m3 | D21: 891 | E21: 165000 | F21: =D21*E21 | G21: =E21*'Gastos Generales'!G23 | H21: =E21*0.09 | I21: =E21+G21+H21 | J21: =D21*I21 | K21: Precio Referencial
A22: 1.17 | B22: Hormigón G-04 Emplantillado Fundaciones | C22: m3 | D22: 62 | E22: 110000 | F22: =D22*E22 | G22: =E22*'Gastos Generales'!G23 | H22: =E22*0.09 | I22: =E22+G22+H22 | J22: =D22*I22 | K22: Precio Referencial
A23: 1.18 | B23: Hormigón G-25 Vigas de Fundación | C23: m3 | D23: 121 | E23: 170000 | F23: =D23*E23 | G23: =E23*'Gastos Generales'!G23 | H23: =E23*0.09 | I23: =E23+G23+H23 | J23: =D23*I23 | K23: Precio Referencial
A24: 1.19 | B24: Hormigón G-25 Pedestales Galpones y Oficinas | C24: m3 | D24: 82 | E24: 185000 | F24: =D24*E24 | G24: =E24*'Gastos Generales'!G23 | H24: =E24*0.09 | I24: =E24+G24+H24 | J24: =D24*I24 | K24: APU ABIERTO G7
A25: 1.20 | B25: Hormigón G-25 Muros Galpones y Oficinas | C25: m3 | D25: 430 | E25: 175000 | F25: =D25*E25 | G25: =E25*'Gastos Generales'!G23 | H25: =E25*0.09 | I25: =E25+G25+H25 | J25: =D25*I25 | K25: Precio Referencial
A26: 1.21 | B26: Enfierradura Fundaciones Zapatas | C26: kg | D26: 42496 | E26: 1340 | F26: =D26*E26 | G26: =E26*'Gastos Generales'!G23 | H26: =E26*0.09 | I26: =E26+G26+H26 | J26: =D26*I26 | K26: Precio Referencial
A27: 1.22 | B27: Enfierradura Vigas de Fundación | C27: kg | D27: 10277 | E27: 1340 | F27: =D27*E27 | G27: =E27*'Gastos Generales'!G23 | H27: =E27*0.09 | I27: =E27+G27+H27 | J27: =D27*I27 | K27: Precio Referencial
A28: 1.23 | B28: Enfierradura Pedestales | C28: kg | D28: 21028 | E28: 1340 | F28: =D28*E28 | G28: =E28*'Gastos Generales'!G23 | H28: =E28*0.09 | I28: =E28+G28+H28 | J28: =D28*I28 | K28: Precio Referencial
A29: 1.24 | B29: Enfierradura Muros | C29: kg | D29: 23885 | E29: 1340 | F29: =D29*E29 | G29: =E29*'Gastos Generales'!G23 | H29: =E29*0.09 | I29: =E29+G29+H29 | J29: =D29*I29 | K29: Precio Referencial
A30: 1.25 | B30: Demolición de Aceras | C30: m2 | D30: 60 | E30: 4450 | F30: =D30*E30 | G30: =E30*'Gastos Generales'!G23 | H30: =E30*0.09 | I30: =E30+G30+H30 | J30: =D30*I30 | K30: Precio Referencial
A31: 1.26 | B31: Remoción de Soleras | C31: m | D31: 45 | E31: 3500 | F31: =D31*E31 | G31: =E31*'Gastos Generales'!G23 | H31: =E31*0.09 | I31: =E31+G31+H31 | J31: =D31*I31 | K31: APU ABIERTO G7
A32: 1.27 | B32: Solera Tipo A | C32: m | D32: 1359 | E32: 13500 | F32: =D32*E32 | G32: =E32*'Gastos Generales'!G23 | H32: =E32*0.09 | I32: =E32+G32+H32 | J32: =D32*I32 | K32: Precio Referencial
A33: SUBTOTAL CAPÍTULO 1 (Costo Directo) | F33: =SUM(F6:F32) | J33: =SUM(J6:J32)
A34: 2.0 ESTRUCTURAS, REVESTIMIENTOS, CUBIERTAS Y TERMINACIONES
A35: 2.1 | B35: Estructura Metalica Montado y Pintado | C35: Kg | D35: 581078 | E35: 2000 | F35: =D35*E35 | G35: =E35*'Gastos Generales'!G23 | H35: =E35*0.09 | I35: =E35+G35+H35 | J35: =D35*I35 | K35: Precio Referencial
A36: 2.2 | B36: Aislación | C36: m2 | D36: 15319 | E36: 4500 | F36: =D36*E36 | G36: =E36*'Gastos Generales'!G23 | H36: =E36*0.09 | I36: =E36+G36+H36 | J36: =D36*I36 | K36: Precio Referencial
A37: 2.3 | B37: Divisiones interiores bodegas | C37: m2 | D37: 7626 | E37: 27000 | F37: =D37*E37 | G37: =E37*'Gastos Generales'!G23 | H37: =E37*0.09 | I37: =E37+G37+H37 | J37: =D37*I37 | K37: Precio Referencial
A38: 2.4 | B38: Oficinas | C38: m2 | D38: 2211 | E38: 500000 | F38: =D38*E38 | G38: =E38*'Gastos Generales'!G23 | H38: =E38*0.09 | I38: =E38+G38+H38 | J38: =D38*I38 | K38: Precio Referencial
A39: 2.5 | B39: Drenes (CuboDren) | C39: m3 | D39: 581 | E39: 48000 | F39: =D39*E39 | G39: =E39*'Gastos Generales'!G23 | H39: =E39*0.09 | I39: =E39+G39+H39 | J39: =D39*I39 | K39: Precio Referencial
A40: 2.6 | B40: Portones Bodegas | C40: N° | D40: 32 | E40: 1800000 | F40: =D40*E40 | G40: =E40*'Gastos Generales'!G23 | H40: =E40*0.09 | I40: =E40+G40+H40 | J40: =D40*I40 | K40: Precio Referencial
A41: 2.7 | B41: Puertas exteriores | C41: N° | D41: 32 | E41: 350000 | F41: =D41*E41 | G41: =E41*'Gastos Generales'!G23 | H41: =E41*0.09 | I41: =E41+G41+H41 | J41: =D41*I41 | K41: Precio Referencial
...

Sheet Gastos Generales
A1: ANÁLISIS DETALLADO DE GASTOS GENERALES — 18 ÍTEMS EXIGIDOS
A2: Proyecto: Bodegas BSL Quilicura | Plazo contractual: 9 meses (Marzo a Noviembre 2026)
A4: N° | B4: Ítem de Gasto General (Enunciado Oficial) | C4: Costo Mensual ($) | D4: Meses de Obra | E4: Costo Fijo / Único ($) | F4: Monto Total Ítem ($) | G4: Justificación Técnica y Composición
A5: 1 | B5: Personal administrativo y directivo del contrato (Administrador, Jefe de Terreno, 2 Ing. Oficina Técnica, Prevencionista APR, Topógrafo) | C5: 23500000 | D5: 9 | E5: 0 | F5: =(C5*D5)+E5 | G5: Sueldos brutos + 32% leyes sociales (FAS): Administrador ($4.5M neto), Jefe de Terreno ($3.2M), 2 Ing. Oficina Técnica ($2.2M c/u), APR ($2.0M), Topógrafo ($1.8M), Jefe Admin ($2.0M).
A6: 2 | B6: Personal auxiliar (2 Alarifes, 2 Bodegueros/Pañoleros, Aseo faena, Servicio de vigilancia 24/7) | C6: 11800000 | D6: 9 | E6: 0 | F6: =(C6*D6)+E6 | G6: Alarifes, bodegueros, aseadores y servicio externo de seguridad 24/7 con guardias certificados OS-10 para predio de 2,5 ha.
A7: 3 | B7: Equipamiento de topografía | C7: 1400000 | D7: 9 | E7: 0 | F7: =(C7*D7)+E7 | G7: Arriendo mensual de 1 Estación Total robótica de alta precisión, 2 niveles ópticos, miras de invar, prismas y GPS submétrico.
A8: 4 | B8: Laboratorio, estudios de suelo y estructural | C8: 4200000 | D8: 9 | E8: 0 | F8: =(C8*D8)+E8 | G8: Ensayes de densidades in situ (cono/nuclear) para 20.000 m3 de rellenos y rotura de probetas cilíndricas (R7, R28) para más de 4.000 m3 de hormigón estructural.
A9: 5 | B9: Insumos de instalaciones (agua potable, electricidad provisoria, gas, internet/telefonía) | C9: 3600000 | D9: 9 | E9: 0 | F9: =(C9*D9)+E9 | G9: Consumo de agua potable en aljibe (50 m3/semana), consumo de energía eléctrica trifásica provisoria de faena, recarga de gas y enlace de fibra óptica dedicado.
A10: 6 | B10: Fotografías, videos, planos | C10: 950000 | D10: 9 | E10: 0 | F10: =(C10*D10)+E10 | G10: Levantamiento aerofotogramétrico mensual con dron, registro fotográfico de hitos para ITO, y ploteo continuo de planos de faena y As-Built finales.
A11: 7 | B11: Movilización de faena | C11: 2800000 | D11: 9 | E11: 0 | F11: =(C11*D11)+E11 | G11: Arriendo, mantención, seguros y tag de 2 camionetas 4x4 doble cabina para supervisión de obra y traslados.
A12: 8 | B12: Combustible | C12: 2400000 | D12: 9 | E12: 0 | F12: =(C12*D12)+E12 | G12: Diésel para camionetas de supervisión y generadores auxiliares de iluminación y faena.
A13: 9 | B13: Viáticos y asignaciones de personal | C13: 1800000 | D13: 9 | E13: 0 | F13: =(C13*D13)+E13 | G13: Servicio de almuerzos en casino de obra y bono de movilización para el personal indirecto de faena.
A14: 10 | B14: Traslado de maquinarias | C14: 0 | D14: 0 | E14: 12500000 | F14: =(C14*D14)+E14 | G14: Transporte en camas bajas de maquinaria pesada: 2 excavadoras 20t, 2 rodillos 10t, 1 motoniveladora y 1 grúa telescópica 50t (ida y vuelta).
A15: 11 | B15: Gastos de representación y oficina central (Overhead) | C15: 7800000 | D15: 9 | E15: 0 | F15: =(C15*D15)+E15 | G15: Prorrateo de costos fijos de casa matriz asignados a la obra: dirección técnica, gerencia de operaciones, legal, contabilidad, ERP y seguros corporativos.
A16: 12 | B16: Boleta de garantía | C16: 0 | D16: 0 | E16: 32000000 | F16: =(C16*D16)+E16 | G16: Costo financiero por emisión bancaria de boletas de garantía de fiel cumplimiento de contrato (5% valor obra) y correcta inversión de anticipo durante el plazo contractual.
... A22: 18 | B22: Instalación de faenas modular (arriendo y montaje) | C22: 3800000 | D22: 9 | E22: 6800000 | F22: =(C22*D22)+E22 | G22: Flete, grúa, montaje, arriendo mensual y posterior desmantelamiento de baterías de contenedores (4 oficinas técnicas, 2 comedores, 2 vestidores con duchas y 1 pañol).
A23: TOTAL GASTOS GENERALES DE LA OBRA | F23: =SUM(F5:F22)
A24: PORCENTAJE DE GASTOS GENERALES RESPECTO AL COSTO DIRECTO | F24: =F23/'Presupuesto General'!F49 | G24: =F23/'Presupuesto General'!F49
